2023-04-03 09:57:44,785 - ERROR - spider.py[:363] - 'NoneType' object has no attribute 'xpath'
Traceback (most recent call last):
  File "c:\Users\MSI-NB\Desktop\FILE\YuFanWenShu\药学\大三下\3. 领域数据学\PJ\微博爬虫\spider.py", line 358, in get_one_weibo
    weibo = self.parse_weibo(weibo_info)
  File "c:\Users\MSI-NB\Desktop\FILE\YuFanWenShu\药学\大三下\3. 领域数据学\PJ\微博爬虫\spider.py", line 260, in parse_weibo
    weibo['text'] = etree.HTML(text_body).xpath('string(.)')
AttributeError: 'NoneType' object has no attribute 'xpath'
2023-04-03 09:58:44,799 - ERROR - spider.py[:363] - 'NoneType' object has no attribute 'xpath'
Traceback (most recent call last):
  File "c:\Users\MSI-NB\Desktop\FILE\YuFanWenShu\药学\大三下\3. 领域数据学\PJ\微博爬虫\spider.py", line 358, in get_one_weibo
    weibo = self.parse_weibo(weibo_info)
  File "c:\Users\MSI-NB\Desktop\FILE\YuFanWenShu\药学\大三下\3. 领域数据学\PJ\微博爬虫\spider.py", line 260, in parse_weibo
    weibo['text'] = etree.HTML(text_body).xpath('string(.)')
AttributeError: 'NoneType' object has no attribute 'xpath'
2023-04-03 10:00:13,135 - ERROR - spider.py[:363] - 'NoneType' object has no attribute 'xpath'
Traceback (most recent call last):
  File "c:\Users\MSI-NB\Desktop\FILE\YuFanWenShu\药学\大三下\3. 领域数据学\PJ\微博爬虫\spider.py", line 358, in get_one_weibo
    weibo = self.parse_weibo(weibo_info)
  File "c:\Users\MSI-NB\Desktop\FILE\YuFanWenShu\药学\大三下\3. 领域数据学\PJ\微博爬虫\spider.py", line 260, in parse_weibo
    weibo['text'] = etree.HTML(text_body).xpath('string(.)')
AttributeError: 'NoneType' object has no attribute 'xpath'
2023-04-03 10:01:02,969 - ERROR - spider.py[:363] - 'NoneType' object has no attribute 'xpath'
Traceback (most recent call last):
  File "c:\Users\MSI-NB\Desktop\FILE\YuFanWenShu\药学\大三下\3. 领域数据学\PJ\微博爬虫\spider.py", line 358, in get_one_weibo
    weibo = self.parse_weibo(weibo_info)
  File "c:\Users\MSI-NB\Desktop\FILE\YuFanWenShu\药学\大三下\3. 领域数据学\PJ\微博爬虫\spider.py", line 260, in parse_weibo
    weibo['text'] = etree.HTML(text_body).xpath('string(.)')
AttributeError: 'NoneType' object has no attribute 'xpath'
2023-04-03 10:01:42,581 - ERROR - spider.py[:363] - 'NoneType' object has no attribute 'xpath'
Traceback (most recent call last):
  File "c:\Users\MSI-NB\Desktop\FILE\YuFanWenShu\药学\大三下\3. 领域数据学\PJ\微博爬虫\spider.py", line 358, in get_one_weibo
    weibo = self.parse_weibo(weibo_info)
  File "c:\Users\MSI-NB\Desktop\FILE\YuFanWenShu\药学\大三下\3. 领域数据学\PJ\微博爬虫\spider.py", line 260, in parse_weibo
    weibo['text'] = etree.HTML(text_body).xpath('string(.)')
AttributeError: 'NoneType' object has no attribute 'xpath'
2023-04-03 10:03:02,864 - ERROR - spider.py[:363] - 'NoneType' object has no attribute 'xpath'
Traceback (most recent call last):
  File "c:\Users\MSI-NB\Desktop\FILE\YuFanWenShu\药学\大三下\3. 领域数据学\PJ\微博爬虫\spider.py", line 358, in get_one_weibo
    weibo = self.parse_weibo(weibo_info)
  File "c:\Users\MSI-NB\Desktop\FILE\YuFanWenShu\药学\大三下\3. 领域数据学\PJ\微博爬虫\spider.py", line 260, in parse_weibo
    weibo['text'] = etree.HTML(text_body).xpath('string(.)')
AttributeError: 'NoneType' object has no attribute 'xpath'
2023-04-03 10:15:50,266 - ERROR - spider.py[:560] - HTTPSConnectionPool(host='m.weibo.cn', port=443): Max retries exceeded with url: /api/container/getIndex?containerid=1005052826785055 (Caused by ProxyError('Cannot connect to proxy.', FileNotFoundError(2, 'No such file or directory')))
Traceback (most recent call last):
  File "E:\zfy\anaconda3\envs\ML\lib\site-packages\urllib3\connectionpool.py", line 696, in urlopen
    self._prepare_proxy(conn)
  File "E:\zfy\anaconda3\envs\ML\lib\site-packages\urllib3\connectionpool.py", line 964, in _prepare_proxy
    conn.connect()
  File "E:\zfy\anaconda3\envs\ML\lib\site-packages\urllib3\connection.py", line 364, in connect
    conn = self._connect_tls_proxy(hostname, conn)
  File "E:\zfy\anaconda3\envs\ML\lib\site-packages\urllib3\connection.py", line 501, in _connect_tls_proxy
    socket = ssl_wrap_socket(
  File "E:\zfy\anaconda3\envs\ML\lib\site-packages\urllib3\util\ssl_.py", line 453, in ssl_wrap_socket
    ssl_sock = _ssl_wrap_socket_impl(sock, context, tls_in_tls)
  File "E:\zfy\anaconda3\envs\ML\lib\site-packages\urllib3\util\ssl_.py", line 495, in _ssl_wrap_socket_impl
    return ssl_context.wrap_socket(sock)
  File "E:\zfy\anaconda3\envs\ML\lib\ssl.py", line 500, in wrap_socket
    return self.sslsocket_class._create(
  File "E:\zfy\anaconda3\envs\ML\lib\ssl.py", line 1040, in _create
    self.do_handshake()
  File "E:\zfy\anaconda3\envs\ML\lib\ssl.py", line 1309, in do_handshake
    self._sslobj.do_handshake()
FileNotFoundError: [Errno 2] No such file or directory

During handling of the above exception, another exception occurred:

Traceback (most recent call last):
  File "E:\zfy\anaconda3\envs\ML\lib\site-packages\requests\adapters.py", line 439, in send
    resp = conn.urlopen(
  File "E:\zfy\anaconda3\envs\ML\lib\site-packages\urllib3\connectionpool.py", line 755, in urlopen
    retries = retries.increment(
  File "E:\zfy\anaconda3\envs\ML\lib\site-packages\urllib3\util\retry.py", line 574, in increment
    raise MaxRetryError(_pool, url, error or ResponseError(cause))
urllib3.exceptions.MaxRetryError: HTTPSConnectionPool(host='m.weibo.cn', port=443): Max retries exceeded with url: /api/container/getIndex?containerid=1005052826785055 (Caused by ProxyError('Cannot connect to proxy.', FileNotFoundError(2, 'No such file or directory')))

During handling of the above exception, another exception occurred:

Traceback (most recent call last):
  File "c:\Users\MSI-NB\Desktop\FILE\YuFanWenShu\药学\大三下\3. 领域数据学\PJ\微博爬虫\spider.py", line 527, in get_pages
    self.get_user_info()
  File "c:\Users\MSI-NB\Desktop\FILE\YuFanWenShu\药学\大三下\3. 领域数据学\PJ\微博爬虫\spider.py", line 97, in get_user_info
    js = self.get_json(params)
  File "c:\Users\MSI-NB\Desktop\FILE\YuFanWenShu\药学\大三下\3. 领域数据学\PJ\微博爬虫\spider.py", line 74, in get_json
    r = requests.get(url,
  File "E:\zfy\anaconda3\envs\ML\lib\site-packages\requests\api.py", line 75, in get
    return request('get', url, params=params, **kwargs)
  File "E:\zfy\anaconda3\envs\ML\lib\site-packages\requests\api.py", line 61, in request
    return session.request(method=method, url=url, **kwargs)
  File "E:\zfy\anaconda3\envs\ML\lib\site-packages\requests\sessions.py", line 542, in request
    resp = self.send(prep, **send_kwargs)
  File "E:\zfy\anaconda3\envs\ML\lib\site-packages\requests\sessions.py", line 655, in send
    r = adapter.send(request, **kwargs)
  File "E:\zfy\anaconda3\envs\ML\lib\site-packages\requests\adapters.py", line 510, in send
    raise ProxyError(e, request=request)
requests.exceptions.ProxyError: HTTPSConnectionPool(host='m.weibo.cn', port=443): Max retries exceeded with url: /api/container/getIndex?containerid=1005052826785055 (Caused by ProxyError('Cannot connect to proxy.', FileNotFoundError(2, 'No such file or directory')))
2023-04-03 10:16:29,913 - ERROR - spider.py[:363] - 'NoneType' object has no attribute 'xpath'
Traceback (most recent call last):
  File "c:\Users\MSI-NB\Desktop\FILE\YuFanWenShu\药学\大三下\3. 领域数据学\PJ\微博爬虫\spider.py", line 358, in get_one_weibo
    weibo = self.parse_weibo(weibo_info)
  File "c:\Users\MSI-NB\Desktop\FILE\YuFanWenShu\药学\大三下\3. 领域数据学\PJ\微博爬虫\spider.py", line 260, in parse_weibo
    weibo['text'] = etree.HTML(text_body).xpath('string(.)')
AttributeError: 'NoneType' object has no attribute 'xpath'
2023-04-03 10:16:38,423 - ERROR - spider.py[:363] - 'NoneType' object has no attribute 'xpath'
Traceback (most recent call last):
  File "c:\Users\MSI-NB\Desktop\FILE\YuFanWenShu\药学\大三下\3. 领域数据学\PJ\微博爬虫\spider.py", line 358, in get_one_weibo
    weibo = self.parse_weibo(weibo_info)
  File "c:\Users\MSI-NB\Desktop\FILE\YuFanWenShu\药学\大三下\3. 领域数据学\PJ\微博爬虫\spider.py", line 260, in parse_weibo
    weibo['text'] = etree.HTML(text_body).xpath('string(.)')
AttributeError: 'NoneType' object has no attribute 'xpath'
2023-04-03 10:16:39,077 - ERROR - spider.py[:363] - Extra data: line 93 column 2 (char 3140)
Traceback (most recent call last):
  File "c:\Users\MSI-NB\Desktop\FILE\YuFanWenShu\药学\大三下\3. 领域数据学\PJ\微博爬虫\spider.py", line 354, in get_one_weibo
    weibo = self.get_long_weibo(weibo_id)
  File "c:\Users\MSI-NB\Desktop\FILE\YuFanWenShu\药学\大三下\3. 领域数据学\PJ\微博爬虫\spider.py", line 153, in get_long_weibo
    js = json.loads(html, strict=False)
  File "E:\zfy\anaconda3\envs\ML\lib\json\__init__.py", line 370, in loads
    return cls(**kw).decode(s)
  File "E:\zfy\anaconda3\envs\ML\lib\json\decoder.py", line 340, in decode
    raise JSONDecodeError("Extra data", s, end)
json.decoder.JSONDecodeError: Extra data: line 93 column 2 (char 3140)
2023-04-03 11:07:35,693 - ERROR - spider.py[:560] - HTTPSConnectionPool(host='m.weibo.cn', port=443): Max retries exceeded with url: /api/container/getIndex?containerid=1005052369507040 (Caused by ProxyError('Cannot connect to proxy.', FileNotFoundError(2, 'No such file or directory')))
Traceback (most recent call last):
  File "E:\zfy\anaconda3\envs\ML\lib\site-packages\urllib3\connectionpool.py", line 696, in urlopen
    self._prepare_proxy(conn)
  File "E:\zfy\anaconda3\envs\ML\lib\site-packages\urllib3\connectionpool.py", line 964, in _prepare_proxy
    conn.connect()
  File "E:\zfy\anaconda3\envs\ML\lib\site-packages\urllib3\connection.py", line 364, in connect
    conn = self._connect_tls_proxy(hostname, conn)
  File "E:\zfy\anaconda3\envs\ML\lib\site-packages\urllib3\connection.py", line 501, in _connect_tls_proxy
    socket = ssl_wrap_socket(
  File "E:\zfy\anaconda3\envs\ML\lib\site-packages\urllib3\util\ssl_.py", line 453, in ssl_wrap_socket
    ssl_sock = _ssl_wrap_socket_impl(sock, context, tls_in_tls)
  File "E:\zfy\anaconda3\envs\ML\lib\site-packages\urllib3\util\ssl_.py", line 495, in _ssl_wrap_socket_impl
    return ssl_context.wrap_socket(sock)
  File "E:\zfy\anaconda3\envs\ML\lib\ssl.py", line 500, in wrap_socket
    return self.sslsocket_class._create(
  File "E:\zfy\anaconda3\envs\ML\lib\ssl.py", line 1040, in _create
    self.do_handshake()
  File "E:\zfy\anaconda3\envs\ML\lib\ssl.py", line 1309, in do_handshake
    self._sslobj.do_handshake()
FileNotFoundError: [Errno 2] No such file or directory

During handling of the above exception, another exception occurred:

Traceback (most recent call last):
  File "E:\zfy\anaconda3\envs\ML\lib\site-packages\requests\adapters.py", line 439, in send
    resp = conn.urlopen(
  File "E:\zfy\anaconda3\envs\ML\lib\site-packages\urllib3\connectionpool.py", line 755, in urlopen
    retries = retries.increment(
  File "E:\zfy\anaconda3\envs\ML\lib\site-packages\urllib3\util\retry.py", line 574, in increment
    raise MaxRetryError(_pool, url, error or ResponseError(cause))
urllib3.exceptions.MaxRetryError: HTTPSConnectionPool(host='m.weibo.cn', port=443): Max retries exceeded with url: /api/container/getIndex?containerid=1005052369507040 (Caused by ProxyError('Cannot connect to proxy.', FileNotFoundError(2, 'No such file or directory')))

During handling of the above exception, another exception occurred:

Traceback (most recent call last):
  File "c:\Users\MSI-NB\Desktop\FILE\YuFanWenShu\药学\大三下\3. 领域数据学\PJ\微博爬虫\spider.py", line 527, in get_pages
    self.get_user_info()
  File "c:\Users\MSI-NB\Desktop\FILE\YuFanWenShu\药学\大三下\3. 领域数据学\PJ\微博爬虫\spider.py", line 97, in get_user_info
    js = self.get_json(params)
  File "c:\Users\MSI-NB\Desktop\FILE\YuFanWenShu\药学\大三下\3. 领域数据学\PJ\微博爬虫\spider.py", line 74, in get_json
    r = requests.get(url,
  File "E:\zfy\anaconda3\envs\ML\lib\site-packages\requests\api.py", line 75, in get
    return request('get', url, params=params, **kwargs)
  File "E:\zfy\anaconda3\envs\ML\lib\site-packages\requests\api.py", line 61, in request
    return session.request(method=method, url=url, **kwargs)
  File "E:\zfy\anaconda3\envs\ML\lib\site-packages\requests\sessions.py", line 542, in request
    resp = self.send(prep, **send_kwargs)
  File "E:\zfy\anaconda3\envs\ML\lib\site-packages\requests\sessions.py", line 655, in send
    r = adapter.send(request, **kwargs)
  File "E:\zfy\anaconda3\envs\ML\lib\site-packages\requests\adapters.py", line 510, in send
    raise ProxyError(e, request=request)
requests.exceptions.ProxyError: HTTPSConnectionPool(host='m.weibo.cn', port=443): Max retries exceeded with url: /api/container/getIndex?containerid=1005052369507040 (Caused by ProxyError('Cannot connect to proxy.', FileNotFoundError(2, 'No such file or directory')))
2023-04-03 11:07:35,801 - ERROR - spider.py[:560] - HTTPSConnectionPool(host='m.weibo.cn', port=443): Max retries exceeded with url: /api/container/getIndex?containerid=1005052826785055 (Caused by ProxyError('Cannot connect to proxy.', FileNotFoundError(2, 'No such file or directory')))
Traceback (most recent call last):
  File "E:\zfy\anaconda3\envs\ML\lib\site-packages\urllib3\connectionpool.py", line 696, in urlopen
    self._prepare_proxy(conn)
  File "E:\zfy\anaconda3\envs\ML\lib\site-packages\urllib3\connectionpool.py", line 964, in _prepare_proxy
    conn.connect()
  File "E:\zfy\anaconda3\envs\ML\lib\site-packages\urllib3\connection.py", line 364, in connect
    conn = self._connect_tls_proxy(hostname, conn)
  File "E:\zfy\anaconda3\envs\ML\lib\site-packages\urllib3\connection.py", line 501, in _connect_tls_proxy
    socket = ssl_wrap_socket(
  File "E:\zfy\anaconda3\envs\ML\lib\site-packages\urllib3\util\ssl_.py", line 453, in ssl_wrap_socket
    ssl_sock = _ssl_wrap_socket_impl(sock, context, tls_in_tls)
  File "E:\zfy\anaconda3\envs\ML\lib\site-packages\urllib3\util\ssl_.py", line 495, in _ssl_wrap_socket_impl
    return ssl_context.wrap_socket(sock)
  File "E:\zfy\anaconda3\envs\ML\lib\ssl.py", line 500, in wrap_socket
    return self.sslsocket_class._create(
  File "E:\zfy\anaconda3\envs\ML\lib\ssl.py", line 1040, in _create
    self.do_handshake()
  File "E:\zfy\anaconda3\envs\ML\lib\ssl.py", line 1309, in do_handshake
    self._sslobj.do_handshake()
FileNotFoundError: [Errno 2] No such file or directory

During handling of the above exception, another exception occurred:

Traceback (most recent call last):
  File "E:\zfy\anaconda3\envs\ML\lib\site-packages\requests\adapters.py", line 439, in send
    resp = conn.urlopen(
  File "E:\zfy\anaconda3\envs\ML\lib\site-packages\urllib3\connectionpool.py", line 755, in urlopen
    retries = retries.increment(
  File "E:\zfy\anaconda3\envs\ML\lib\site-packages\urllib3\util\retry.py", line 574, in increment
    raise MaxRetryError(_pool, url, error or ResponseError(cause))
urllib3.exceptions.MaxRetryError: HTTPSConnectionPool(host='m.weibo.cn', port=443): Max retries exceeded with url: /api/container/getIndex?containerid=1005052826785055 (Caused by ProxyError('Cannot connect to proxy.', FileNotFoundError(2, 'No such file or directory')))

During handling of the above exception, another exception occurred:

Traceback (most recent call last):
  File "c:\Users\MSI-NB\Desktop\FILE\YuFanWenShu\药学\大三下\3. 领域数据学\PJ\微博爬虫\spider.py", line 527, in get_pages
    self.get_user_info()
  File "c:\Users\MSI-NB\Desktop\FILE\YuFanWenShu\药学\大三下\3. 领域数据学\PJ\微博爬虫\spider.py", line 97, in get_user_info
    js = self.get_json(params)
  File "c:\Users\MSI-NB\Desktop\FILE\YuFanWenShu\药学\大三下\3. 领域数据学\PJ\微博爬虫\spider.py", line 74, in get_json
    r = requests.get(url,
  File "E:\zfy\anaconda3\envs\ML\lib\site-packages\requests\api.py", line 75, in get
    return request('get', url, params=params, **kwargs)
  File "E:\zfy\anaconda3\envs\ML\lib\site-packages\requests\api.py", line 61, in request
    return session.request(method=method, url=url, **kwargs)
  File "E:\zfy\anaconda3\envs\ML\lib\site-packages\requests\sessions.py", line 542, in request
    resp = self.send(prep, **send_kwargs)
  File "E:\zfy\anaconda3\envs\ML\lib\site-packages\requests\sessions.py", line 655, in send
    r = adapter.send(request, **kwargs)
  File "E:\zfy\anaconda3\envs\ML\lib\site-packages\requests\adapters.py", line 510, in send
    raise ProxyError(e, request=request)
requests.exceptions.ProxyError: HTTPSConnectionPool(host='m.weibo.cn', port=443): Max retries exceeded with url: /api/container/getIndex?containerid=1005052826785055 (Caused by ProxyError('Cannot connect to proxy.', FileNotFoundError(2, 'No such file or directory')))
2023-04-03 11:08:39,716 - ERROR - spider.py[:560] - HTTPSConnectionPool(host='m.weibo.cn', port=443): Max retries exceeded with url: /api/container/getIndex?containerid=1005052369507040 (Caused by ProxyError('Cannot connect to proxy.', FileNotFoundError(2, 'No such file or directory')))
Traceback (most recent call last):
  File "E:\zfy\anaconda3\envs\ML\lib\site-packages\urllib3\connectionpool.py", line 696, in urlopen
    self._prepare_proxy(conn)
  File "E:\zfy\anaconda3\envs\ML\lib\site-packages\urllib3\connectionpool.py", line 964, in _prepare_proxy
    conn.connect()
  File "E:\zfy\anaconda3\envs\ML\lib\site-packages\urllib3\connection.py", line 364, in connect
    conn = self._connect_tls_proxy(hostname, conn)
  File "E:\zfy\anaconda3\envs\ML\lib\site-packages\urllib3\connection.py", line 501, in _connect_tls_proxy
    socket = ssl_wrap_socket(
  File "E:\zfy\anaconda3\envs\ML\lib\site-packages\urllib3\util\ssl_.py", line 453, in ssl_wrap_socket
    ssl_sock = _ssl_wrap_socket_impl(sock, context, tls_in_tls)
  File "E:\zfy\anaconda3\envs\ML\lib\site-packages\urllib3\util\ssl_.py", line 495, in _ssl_wrap_socket_impl
    return ssl_context.wrap_socket(sock)
  File "E:\zfy\anaconda3\envs\ML\lib\ssl.py", line 500, in wrap_socket
    return self.sslsocket_class._create(
  File "E:\zfy\anaconda3\envs\ML\lib\ssl.py", line 1040, in _create
    self.do_handshake()
  File "E:\zfy\anaconda3\envs\ML\lib\ssl.py", line 1309, in do_handshake
    self._sslobj.do_handshake()
FileNotFoundError: [Errno 2] No such file or directory

During handling of the above exception, another exception occurred:

Traceback (most recent call last):
  File "E:\zfy\anaconda3\envs\ML\lib\site-packages\requests\adapters.py", line 439, in send
    resp = conn.urlopen(
  File "E:\zfy\anaconda3\envs\ML\lib\site-packages\urllib3\connectionpool.py", line 755, in urlopen
    retries = retries.increment(
  File "E:\zfy\anaconda3\envs\ML\lib\site-packages\urllib3\util\retry.py", line 574, in increment
    raise MaxRetryError(_pool, url, error or ResponseError(cause))
urllib3.exceptions.MaxRetryError: HTTPSConnectionPool(host='m.weibo.cn', port=443): Max retries exceeded with url: /api/container/getIndex?containerid=1005052369507040 (Caused by ProxyError('Cannot connect to proxy.', FileNotFoundError(2, 'No such file or directory')))

During handling of the above exception, another exception occurred:

Traceback (most recent call last):
  File "c:\Users\MSI-NB\Desktop\FILE\YuFanWenShu\药学\大三下\3. 领域数据学\PJ\微博爬虫\spider.py", line 527, in get_pages
    self.get_user_info()
  File "c:\Users\MSI-NB\Desktop\FILE\YuFanWenShu\药学\大三下\3. 领域数据学\PJ\微博爬虫\spider.py", line 97, in get_user_info
    js = self.get_json(params)
  File "c:\Users\MSI-NB\Desktop\FILE\YuFanWenShu\药学\大三下\3. 领域数据学\PJ\微博爬虫\spider.py", line 74, in get_json
    r = requests.get(url,
  File "E:\zfy\anaconda3\envs\ML\lib\site-packages\requests\api.py", line 75, in get
    return request('get', url, params=params, **kwargs)
  File "E:\zfy\anaconda3\envs\ML\lib\site-packages\requests\api.py", line 61, in request
    return session.request(method=method, url=url, **kwargs)
  File "E:\zfy\anaconda3\envs\ML\lib\site-packages\requests\sessions.py", line 542, in request
    resp = self.send(prep, **send_kwargs)
  File "E:\zfy\anaconda3\envs\ML\lib\site-packages\requests\sessions.py", line 655, in send
    r = adapter.send(request, **kwargs)
  File "E:\zfy\anaconda3\envs\ML\lib\site-packages\requests\adapters.py", line 510, in send
    raise ProxyError(e, request=request)
requests.exceptions.ProxyError: HTTPSConnectionPool(host='m.weibo.cn', port=443): Max retries exceeded with url: /api/container/getIndex?containerid=1005052369507040 (Caused by ProxyError('Cannot connect to proxy.', FileNotFoundError(2, 'No such file or directory')))
2023-04-03 11:08:39,850 - ERROR - spider.py[:560] - HTTPSConnectionPool(host='m.weibo.cn', port=443): Max retries exceeded with url: /api/container/getIndex?containerid=1005052826785055 (Caused by ProxyError('Cannot connect to proxy.', FileNotFoundError(2, 'No such file or directory')))
Traceback (most recent call last):
  File "E:\zfy\anaconda3\envs\ML\lib\site-packages\urllib3\connectionpool.py", line 696, in urlopen
    self._prepare_proxy(conn)
  File "E:\zfy\anaconda3\envs\ML\lib\site-packages\urllib3\connectionpool.py", line 964, in _prepare_proxy
    conn.connect()
  File "E:\zfy\anaconda3\envs\ML\lib\site-packages\urllib3\connection.py", line 364, in connect
    conn = self._connect_tls_proxy(hostname, conn)
  File "E:\zfy\anaconda3\envs\ML\lib\site-packages\urllib3\connection.py", line 501, in _connect_tls_proxy
    socket = ssl_wrap_socket(
  File "E:\zfy\anaconda3\envs\ML\lib\site-packages\urllib3\util\ssl_.py", line 453, in ssl_wrap_socket
    ssl_sock = _ssl_wrap_socket_impl(sock, context, tls_in_tls)
  File "E:\zfy\anaconda3\envs\ML\lib\site-packages\urllib3\util\ssl_.py", line 495, in _ssl_wrap_socket_impl
    return ssl_context.wrap_socket(sock)
  File "E:\zfy\anaconda3\envs\ML\lib\ssl.py", line 500, in wrap_socket
    return self.sslsocket_class._create(
  File "E:\zfy\anaconda3\envs\ML\lib\ssl.py", line 1040, in _create
    self.do_handshake()
  File "E:\zfy\anaconda3\envs\ML\lib\ssl.py", line 1309, in do_handshake
    self._sslobj.do_handshake()
FileNotFoundError: [Errno 2] No such file or directory

During handling of the above exception, another exception occurred:

Traceback (most recent call last):
  File "E:\zfy\anaconda3\envs\ML\lib\site-packages\requests\adapters.py", line 439, in send
    resp = conn.urlopen(
  File "E:\zfy\anaconda3\envs\ML\lib\site-packages\urllib3\connectionpool.py", line 755, in urlopen
    retries = retries.increment(
  File "E:\zfy\anaconda3\envs\ML\lib\site-packages\urllib3\util\retry.py", line 574, in increment
    raise MaxRetryError(_pool, url, error or ResponseError(cause))
urllib3.exceptions.MaxRetryError: HTTPSConnectionPool(host='m.weibo.cn', port=443): Max retries exceeded with url: /api/container/getIndex?containerid=1005052826785055 (Caused by ProxyError('Cannot connect to proxy.', FileNotFoundError(2, 'No such file or directory')))

During handling of the above exception, another exception occurred:

Traceback (most recent call last):
  File "c:\Users\MSI-NB\Desktop\FILE\YuFanWenShu\药学\大三下\3. 领域数据学\PJ\微博爬虫\spider.py", line 527, in get_pages
    self.get_user_info()
  File "c:\Users\MSI-NB\Desktop\FILE\YuFanWenShu\药学\大三下\3. 领域数据学\PJ\微博爬虫\spider.py", line 97, in get_user_info
    js = self.get_json(params)
  File "c:\Users\MSI-NB\Desktop\FILE\YuFanWenShu\药学\大三下\3. 领域数据学\PJ\微博爬虫\spider.py", line 74, in get_json
    r = requests.get(url,
  File "E:\zfy\anaconda3\envs\ML\lib\site-packages\requests\api.py", line 75, in get
    return request('get', url, params=params, **kwargs)
  File "E:\zfy\anaconda3\envs\ML\lib\site-packages\requests\api.py", line 61, in request
    return session.request(method=method, url=url, **kwargs)
  File "E:\zfy\anaconda3\envs\ML\lib\site-packages\requests\sessions.py", line 542, in request
    resp = self.send(prep, **send_kwargs)
  File "E:\zfy\anaconda3\envs\ML\lib\site-packages\requests\sessions.py", line 655, in send
    r = adapter.send(request, **kwargs)
  File "E:\zfy\anaconda3\envs\ML\lib\site-packages\requests\adapters.py", line 510, in send
    raise ProxyError(e, request=request)
requests.exceptions.ProxyError: HTTPSConnectionPool(host='m.weibo.cn', port=443): Max retries exceeded with url: /api/container/getIndex?containerid=1005052826785055 (Caused by ProxyError('Cannot connect to proxy.', FileNotFoundError(2, 'No such file or directory')))
2023-04-03 11:10:46,445 - ERROR - spider.py[:363] - 'NoneType' object has no attribute 'xpath'
Traceback (most recent call last):
  File "c:\Users\MSI-NB\Desktop\FILE\YuFanWenShu\药学\大三下\3. 领域数据学\PJ\微博爬虫\spider.py", line 358, in get_one_weibo
    weibo = self.parse_weibo(weibo_info)
  File "c:\Users\MSI-NB\Desktop\FILE\YuFanWenShu\药学\大三下\3. 领域数据学\PJ\微博爬虫\spider.py", line 260, in parse_weibo
    weibo['text'] = etree.HTML(text_body).xpath('string(.)')
AttributeError: 'NoneType' object has no attribute 'xpath'
2023-04-03 11:10:52,066 - ERROR - spider.py[:363] - 'NoneType' object has no attribute 'xpath'
Traceback (most recent call last):
  File "c:\Users\MSI-NB\Desktop\FILE\YuFanWenShu\药学\大三下\3. 领域数据学\PJ\微博爬虫\spider.py", line 358, in get_one_weibo
    weibo = self.parse_weibo(weibo_info)
  File "c:\Users\MSI-NB\Desktop\FILE\YuFanWenShu\药学\大三下\3. 领域数据学\PJ\微博爬虫\spider.py", line 260, in parse_weibo
    weibo['text'] = etree.HTML(text_body).xpath('string(.)')
AttributeError: 'NoneType' object has no attribute 'xpath'
2023-04-03 11:10:59,803 - ERROR - spider.py[:363] - Extra data: line 93 column 2 (char 3140)
Traceback (most recent call last):
  File "c:\Users\MSI-NB\Desktop\FILE\YuFanWenShu\药学\大三下\3. 领域数据学\PJ\微博爬虫\spider.py", line 354, in get_one_weibo
    weibo = self.get_long_weibo(weibo_id)
  File "c:\Users\MSI-NB\Desktop\FILE\YuFanWenShu\药学\大三下\3. 领域数据学\PJ\微博爬虫\spider.py", line 153, in get_long_weibo
    js = json.loads(html, strict=False)
  File "E:\zfy\anaconda3\envs\ML\lib\json\__init__.py", line 370, in loads
    return cls(**kw).decode(s)
  File "E:\zfy\anaconda3\envs\ML\lib\json\decoder.py", line 340, in decode
    raise JSONDecodeError("Extra data", s, end)
json.decoder.JSONDecodeError: Extra data: line 93 column 2 (char 3140)
2023-04-03 11:12:11,244 - ERROR - spider.py[:363] - 'NoneType' object has no attribute 'xpath'
Traceback (most recent call last):
  File "c:\Users\MSI-NB\Desktop\FILE\YuFanWenShu\药学\大三下\3. 领域数据学\PJ\微博爬虫\spider.py", line 358, in get_one_weibo
    weibo = self.parse_weibo(weibo_info)
  File "c:\Users\MSI-NB\Desktop\FILE\YuFanWenShu\药学\大三下\3. 领域数据学\PJ\微博爬虫\spider.py", line 260, in parse_weibo
    weibo['text'] = etree.HTML(text_body).xpath('string(.)')
AttributeError: 'NoneType' object has no attribute 'xpath'
2023-04-03 11:12:18,358 - ERROR - spider.py[:363] - 'NoneType' object has no attribute 'xpath'
Traceback (most recent call last):
  File "c:\Users\MSI-NB\Desktop\FILE\YuFanWenShu\药学\大三下\3. 领域数据学\PJ\微博爬虫\spider.py", line 358, in get_one_weibo
    weibo = self.parse_weibo(weibo_info)
  File "c:\Users\MSI-NB\Desktop\FILE\YuFanWenShu\药学\大三下\3. 领域数据学\PJ\微博爬虫\spider.py", line 260, in parse_weibo
    weibo['text'] = etree.HTML(text_body).xpath('string(.)')
AttributeError: 'NoneType' object has no attribute 'xpath'
2023-04-03 11:12:28,043 - ERROR - spider.py[:363] - Extra data: line 93 column 2 (char 3140)
Traceback (most recent call last):
  File "c:\Users\MSI-NB\Desktop\FILE\YuFanWenShu\药学\大三下\3. 领域数据学\PJ\微博爬虫\spider.py", line 354, in get_one_weibo
    weibo = self.get_long_weibo(weibo_id)
  File "c:\Users\MSI-NB\Desktop\FILE\YuFanWenShu\药学\大三下\3. 领域数据学\PJ\微博爬虫\spider.py", line 153, in get_long_weibo
    js = json.loads(html, strict=False)
  File "E:\zfy\anaconda3\envs\ML\lib\json\__init__.py", line 370, in loads
    return cls(**kw).decode(s)
  File "E:\zfy\anaconda3\envs\ML\lib\json\decoder.py", line 340, in decode
    raise JSONDecodeError("Extra data", s, end)
json.decoder.JSONDecodeError: Extra data: line 93 column 2 (char 3140)
2023-04-03 11:14:06,434 - ERROR - spider.py[:363] - 'NoneType' object has no attribute 'xpath'
Traceback (most recent call last):
  File "c:\Users\MSI-NB\Desktop\FILE\YuFanWenShu\药学\大三下\3. 领域数据学\PJ\微博爬虫\spider.py", line 358, in get_one_weibo
    weibo = self.parse_weibo(weibo_info)
  File "c:\Users\MSI-NB\Desktop\FILE\YuFanWenShu\药学\大三下\3. 领域数据学\PJ\微博爬虫\spider.py", line 260, in parse_weibo
    weibo['text'] = etree.HTML(text_body).xpath('string(.)')
AttributeError: 'NoneType' object has no attribute 'xpath'
2023-04-03 11:14:18,732 - ERROR - spider.py[:363] - 'NoneType' object has no attribute 'xpath'
Traceback (most recent call last):
  File "c:\Users\MSI-NB\Desktop\FILE\YuFanWenShu\药学\大三下\3. 领域数据学\PJ\微博爬虫\spider.py", line 358, in get_one_weibo
    weibo = self.parse_weibo(weibo_info)
  File "c:\Users\MSI-NB\Desktop\FILE\YuFanWenShu\药学\大三下\3. 领域数据学\PJ\微博爬虫\spider.py", line 260, in parse_weibo
    weibo['text'] = etree.HTML(text_body).xpath('string(.)')
AttributeError: 'NoneType' object has no attribute 'xpath'
2023-04-03 11:14:19,380 - ERROR - spider.py[:363] - Extra data: line 93 column 2 (char 3140)
Traceback (most recent call last):
  File "c:\Users\MSI-NB\Desktop\FILE\YuFanWenShu\药学\大三下\3. 领域数据学\PJ\微博爬虫\spider.py", line 354, in get_one_weibo
    weibo = self.get_long_weibo(weibo_id)
  File "c:\Users\MSI-NB\Desktop\FILE\YuFanWenShu\药学\大三下\3. 领域数据学\PJ\微博爬虫\spider.py", line 153, in get_long_weibo
    js = json.loads(html, strict=False)
  File "E:\zfy\anaconda3\envs\ML\lib\json\__init__.py", line 370, in loads
    return cls(**kw).decode(s)
  File "E:\zfy\anaconda3\envs\ML\lib\json\decoder.py", line 340, in decode
    raise JSONDecodeError("Extra data", s, end)
json.decoder.JSONDecodeError: Extra data: line 93 column 2 (char 3140)
2023-04-03 11:25:30,439 - ERROR - spider.py[:363] - 'NoneType' object has no attribute 'xpath'
Traceback (most recent call last):
  File "c:\Users\MSI-NB\Desktop\FILE\YuFanWenShu\药学\大三下\3. 领域数据学\PJ\weiboSpyder\spider.py", line 358, in get_one_weibo
    weibo = self.parse_weibo(weibo_info)
  File "c:\Users\MSI-NB\Desktop\FILE\YuFanWenShu\药学\大三下\3. 领域数据学\PJ\weiboSpyder\spider.py", line 260, in parse_weibo
    weibo['text'] = etree.HTML(text_body).xpath('string(.)')
AttributeError: 'NoneType' object has no attribute 'xpath'
2023-04-03 11:25:31,772 - ERROR - spider.py[:363] - 'NoneType' object has no attribute 'xpath'
Traceback (most recent call last):
  File "c:\Users\MSI-NB\Desktop\FILE\YuFanWenShu\药学\大三下\3. 领域数据学\PJ\weiboSpyder\spider.py", line 358, in get_one_weibo
    weibo = self.parse_weibo(weibo_info)
  File "c:\Users\MSI-NB\Desktop\FILE\YuFanWenShu\药学\大三下\3. 领域数据学\PJ\weiboSpyder\spider.py", line 260, in parse_weibo
    weibo['text'] = etree.HTML(text_body).xpath('string(.)')
AttributeError: 'NoneType' object has no attribute 'xpath'
2023-04-03 11:25:32,462 - ERROR - spider.py[:363] - Extra data: line 93 column 2 (char 3140)
Traceback (most recent call last):
  File "c:\Users\MSI-NB\Desktop\FILE\YuFanWenShu\药学\大三下\3. 领域数据学\PJ\weiboSpyder\spider.py", line 354, in get_one_weibo
    weibo = self.get_long_weibo(weibo_id)
  File "c:\Users\MSI-NB\Desktop\FILE\YuFanWenShu\药学\大三下\3. 领域数据学\PJ\weiboSpyder\spider.py", line 153, in get_long_weibo
    js = json.loads(html, strict=False)
  File "E:\zfy\anaconda3\envs\ML\lib\json\__init__.py", line 370, in loads
    return cls(**kw).decode(s)
  File "E:\zfy\anaconda3\envs\ML\lib\json\decoder.py", line 340, in decode
    raise JSONDecodeError("Extra data", s, end)
json.decoder.JSONDecodeError: Extra data: line 93 column 2 (char 3140)
